Workbook

Sheet 표지
B7: 요구사항명세서
B9: PRJ-001
D17: 작성자 | F17: 작성자
D18: 작성 상태
D19: 최종 개정일
A22: 본 문서는 어떠한 경우에도 공식적인 허가 없이 복사하거나 외부로 유출하는 일체의 행위를 금함

Sheet 개정이력
E2: 개정 이력
A4: 일자 | B4: 버전 | C4: 주요 내용 | I4: 작성자 | J4: 승인자
A5: 2026-06-11 | B5: 0.1 | C5: 초안 | I5: 작성자

Sheet (요건분리 전)요구사항명세서
A1: Biz요건ID | B1: Biz요건명 | C1: 요구사항구분 | D1: 생성단계 | E1: 상태구분 | F1: 출처 | G1: 요구사항ID | H1: 요구사항명 | I1: 기능/비기능요구사항(취합정리 5/25) | J1: 사용자권한요구사항 | K1: 의뢰부서 | L1: 요구사항처리담당팀 | M1: 검토 상태 | N1: 검토의견 | O1: 변경요구사항ID | P1: 변경일 | Q1: 근기문서 | R1: ACE | S1: 반영점검사항 | T1: 반영여부(5.26) | U1: 수행사 담당자 | V1: 업무상세 | W1: 요구사항추적표담당자 | X1: 특이사항 | Y1: 조건부승인 확정예정일자(YYYY-MM-DD)
A2: Biz-0001 | B2: 공통 | C2: 기능 | D2: 요구사항정의 | E2: 신규 | F2: 구축요건정의서 | G2: BSR-00001 | H2: Login is required | I2: Login is required. Users must authenticate before viewing data.
T7: 조건부수용
T8: 조건부수용
T13: 조건부수용
T16: 조건부수용
T17: 6/10까지협의
T19: 조건부수용
T23: 6/3까지협의
T27: 6/3까지 협의
T28: 조건부수용
T29: 6/3까지 협의

Sheet 요구사항명세서
A1: 업무 | B1: 구분 | C1: Biz요건ID | D1: Biz요건명 | E1: 요구사항구분 | F1: 생성단계 | G1: 상태구분 | H1: 출처 | I1: 요구사항ID | J1: 요구사항명 | K1: 기능/비기능요구사항 | L1: 사용자권한요구사항 | M1: 의뢰부서 | N1: 요구사항처리담당팀 | O1: 검토상태 | P1: 검토의견 | Q1: 변경요구사항ID | R1: 변경일 | S1: 근기문서 | T1: 구분
A2: 공통 | B2: 공통 | C2: Biz-0001 | D2: 공통 | E2: 기능 | F2: 요구사항정의 | G2: 신규 | H2: 구축요건정의서 | I2: BSR-00001 | J2: Login is required | K2: Login is required. Users must authenticate before viewing data.

Sheet ※(요약)확정현황
B1: < 전체현황 >
K2: 실시간 | M2: <전주대비 증감>
B3: 개수 : 요구사항ID | C3: 검토상태 | I3: 총합계 (S = A+B+C+D+E+F) | J3: 진행율 (A+B+C+E+F)/S | K3: 수용율 (A+B)/S | M3: 검토상태 | Q3: 총합계 (S = A+B+C+D) | R3: 진행율 (A+B+C)/S | S3: 수용율 (A+B)/S
B4: 행 레이블 | C4: 승인(개발가능) (A) | D4: 조건부승인(일부개발가능) (B) | E4: 거부(삭제) (C ) | F4: 거부-이관 ( E) | G4: 거부-통폐합 (F) | H4: 미정 (D) | M4: 승인(개발가능) (A) | N4: 조건부승인(일부개발가능) (B) | O4: 거부(개발불가) (C ) | P4: 미정 (D)
B5: UXUI | C5: =COUNTIFS(#REF!,'※(요약)확정현황'!B5,#REF!,"승인") | D5: =COUNTIFS(#REF!,'※(요약)확정현황'!B5,#REF!,"조건부승인") | E5: =COUNTIFS(#REF!,'※(요약)확정현황'!B5,#REF!,"거부") | F5: =COUNTIFS(#REF!,'※(요약)확정현황'!B5,#REF!,"거부-이관") | G5: =COUNTIFS(#REF!,'※(요약)확정현황'!B5,#REF!,"거부-통폐합") | H5: =COUNTIFS(#REF!,'※(요약)확정현황'!B5,#REF!,"") | I5: =SUM(C5:H5) | J5: =(C5+D5+E5+F5+G5)/I5 | K5: =(C5+D5)/I5 | M5: =C5-C16 | N5: =D5-D16 | O5: =E5-E16 | P5: =H5-H16 | Q5: =I5-I16 | R5: =J5-J16 | S5: =K5-K16
B6: 응용개발-공통뱅킹 | C6: =COUNTIFS(#REF!,'※(요약)확정현황'!B6,#REF!,"승인") | D6: =COUNTIFS(#REF!,'※(요약)확정현황'!B6,#REF!,"조건부승인") | E6: =COUNTIFS(#REF!,'※(요약)확정현황'!B6,#REF!,"거부") | F6: =COUNTIFS(#REF!,'※(요약)확정현황'!B6,#REF!,"거부-이관") | G6: =COUNTIFS(#REF!,'※(요약)확정현황'!B6,#REF!,"거부-통폐합") | H6: =COUNTIFS(#REF!,'※(요약)확정현황'!B6,#REF!,"") | I6: =SUM(C6:H6) | J6: =(C6+D6+E6+F6+G6)/I6 | K6: =(C6+D6)/I6 | M6: =C6-C17 | N6: =D6-D17 | O6: =E6-E17 | P6: =H6-H17 | Q6: =I6-I17 | R6: =J6-J17 | S6: =K6-K17
B7: 응용개발-대응개발 | C7: =COUNTIFS(#REF!,'※(요약)확정현황'!B7,#REF!,"승인") | D7: =COUNTIFS(#REF!,'※(요약)확정현황'!B7,#REF!,"조건부승인") | E7: =COUNTIFS(#REF!,'※(요약)확정현황'!B7,#REF!,"거부") | F7: =COUNTIFS(#REF!,'※(요약)확정현황'!B7,#REF!,"거부-이관") | G7: =COUNTIFS(#REF!,'※(요약)확정현황'!B7,#REF!,"거부-통폐합") | H7: =COUNTIFS(#REF!,'※(요약)확정현황'!B7,#REF!,"") | I7: =SUM(C7:H7) | J7: =(C7+D7+E7+F7+G7)/I7 | K7: =(C7+D7)/I7 | M7: =C7-C18 | N7: =D7-D18 | O7: =E7-E18 | P7: =H7-H18 | Q7: =I7-I18 | R7: =J7-J18 | S7: =K7-K18
B8: 응용개발-모바일 | C8: =COUNTIFS(#REF!,'※(요약)확정현황'!B8,#REF!,"승인") | D8: =COUNTIFS(#REF!,'※(요약)확정현황'!B8,#REF!,"조건부승인") | E8: =COUNTIFS(#REF!,'※(요약)확정현황'!B8,#REF!,"거부") | F8: =COUNTIFS(#REF!,'※(요약)확정현황'!B8,#REF!,"거부-이관") | G8: =COUNTIFS(#REF!,'※(요약)확정현황'!B8,#REF!,"거부-통폐합") | H8: =COUNTIFS(#REF!,'※(요약)확정현황'!B8,#REF!,"") | I8: =SUM(C8:H8) | J8: =(C8+D8+E8+F8+G8)/I8 | K8: =(C8+D8)/I8 | M8: =C8-C19 | N8: =D8-D19 | O8: =E8-E19 | P8: =H8-H19 | Q8: =I8-I19 | R8: =J8-J19 | S8: =K8-K19
B9: 인프라 | C9: =COUNTIFS(#REF!,'※(요약)확정현황'!B9,#REF!,"승인") | D9: =COUNTIFS(#REF!,'※(요약)확정현황'!B9,#REF!,"조건부승인") | E9: =COUNTIFS(#REF!,'※(요약)확정현황'!B9,#REF!,"거부") | F9: =COUNTIFS(#REF!,'※(요약)확정현황'!B9,#REF!,"거부-이관") | G9: =COUNTIFS(#REF!,'※(요약)확정현황'!B9,#REF!,"거부-통폐합") | H9: =COUNTIFS(#REF!,'※(요약)확정현황'!B9,#REF!,"") | I9: =SUM(C9:H9) | J9: =(C9+D9+E9+F9+G9)/I9 | K9: =(C9+D9)/I9 | M9: =C9-C20 | N9: =D9-D20 | O9: =E9-E20 | P9: =H9-H20 | Q9: =I9-I20 | R9: =J9-J20 | S9: =K9-K20
B10: 전문위원 | C10: =COUNTIFS(#REF!,'※(요약)확정현황'!B10,#REF!,"승인") | D10: =COUNTIFS(#REF!,'※(요약)확정현황'!B10,#REF!,"조건부승인") | E10: =COUNTIFS(#REF!,'※(요약)확정현황'!B10,#REF!,"거부") | F10: =COUNTIFS(#REF!,'※(요약)확정현황'!B10,#REF!,"거부-이관") | G10: =COUNTIFS(#REF!,'※(요약)확정현황'!B10,#REF!,"거부-통폐합") | H10: =COUNTIFS(#REF!,'※(요약)확정현황'!B10,#REF!,"") | I10: =SUM(C10:H10) | J10: =(C10+D10+E10+F10+G10)/I10 | K10: =(C10+D10)/I10
B11: 총합계 | C11: =SUM(C5:C10) | D11: =SUM(D5:D10) | E11: =SUM(E5:E10) | F11: =SUM(F5:F10) | G11: =SUM(G5:G10) | H11: =SUM(H5:H10) | I11: =SUM(I5:I10) | J11: =(C11+D11+E11+F11+G11)/I11 | K11: =(C11+D11)/I11 | M11: =SUM(M5:M9) | N11: =SUM(N5:N9) | O11: =SUM(O5:O9) | P11: =SUM(P5:P9) | Q11: =SUM(Q5:Q9) | R11: =J11-J21 | S11: =K11-K21
B13: <전주-9주차> | K13: 2/17 18시기준
B14: 개수 : 요구사항ID | C14: 검토상태 | I14: 총합계 (S = A+B+C+D+E) | J14: 진행율 (A+B+C+E)/S | K14: 수용율 (A+B)/S
B15: 행 레이블 | C15: 승인(개발가능) (A) | D15: 조건부승인(일부개발가능) (B) | E15: 거부(삭제) (C ) | F15: 거부-이관 ( E) | H15: 미정 (D)
B16: UXUI | C16: 72 | D16: 33 | E16: 28 | F16: 0 | H16: 71 | I16: 201 | J16: 0.65 | K16: 0.51
B17: 응용개발-공통뱅킹 | C17: 4 | D17: 0 | E17: 0 | F17: 0 | H17: 1 | I17: 5 | J17: 0.8 | K17: 0.8
B18: 응용개발-대응개발 | C18: 0 | D18: 0 | E18: 0 | F18: 0 | H18: 1 | I18: 1 | J18: 0 | K18: 0
B19: 응용개발-모바일 | C19: 4 | D19: 0 | E19: 0 | F19: 0 | H19: 0 | I19: 4 | J19: 1 | K19: 1
B20: 인프라 | C20: 26 | D20: 2 | E20: 0 | F20: 0 | H20: 1 | I20: 29 | J20: 0.97 | K20: 0.97
B21: 총합계 | C21: 106 | D21: 35 | E21: 28 | F21: 0 | H21: 74 | I21: 240 | J21: 0.7 | K21: 0.58

Sheet (참고)요구사항ID채번
B1: ** 요구사항ID채번시 업무별 아래규칙을 준수바랍니다. ** 관리위치 : \200.프로젝트표준\240.개발_양식템플릿\01.요구사항정의\NEW KB스타뱅킹구축-요구사항ID 채번규칙.xlsx
B2: 팀명 | C2: 업무대분류 | D2: 업무세분류 | E2: 요구사항ID범위 | F2: 비고 | H2: 팀명
B3: 전문위원 | C3: - | D3: - | E3: AP코드-10000 | F3: 요구사항ID증가는 10단위로 반영(추후 누락분 반영을 위한 최소간격 유지) | H3: 전문위원
B4: 인프라 | C4: - | D4: - | E4: AP코드-90000 | H4: 인프라
B5: 공통 | C5: 공통 | D5: 로그인/인증 | E5: AP코드-21000 | H5: 공통
B6: 공통 | D6: 계열사/외부연계 | E6: AP코드-22000 | H6: 뱅킹
B7: 공통 | D7: 기타 공통 | E7: AP코드-23000 | H7: 상품/외환
B8: 공통 | D8: 인증센터 | E8: AP코드-24000 | H8: 자산관리
B9: 공통 | D9: UX전문위원 | E9: AP코드-25000 | H9: 모바일
B10: 공통 | D10: 디자인 | E10: AP코드-26000
B11: 공통 | D11: 퍼블리싱 | E11: AP코드-27000
B12: 뱅킹 | C12: 조회 | D12: - | E12: AP코드-30000
B13: 뱅킹 | C13: 이체 | D13: - | E13: AP코드-31000
B14: 공통 | C14: 관리 | D14: - | E14: AP코드-40000
B15: 공통 | C15: 인증/보안 | D15: - | E15: AP코드-41000
B16: 뱅킹 | C16: 공과금 | D16: - | E16: AP코드-42000
B17: 상품/외환 | C17: 외환 | D17: - | E17: AP코드-50000
B18: 자산관리 | C18: 금융서비스 | D18: - | E18: AP코드-60000
B19: 자산관리 | D19: 자산관리 | E19: AP코드-61000
B20: 상품/외환 | C20: 상품 | D20: 상품라운지 | E20: AP코드-70000
B21: 상품/외환 | D21: 예금 | E21: AP코드-71000
B22: 상품/외환 | D22: 대출 | E22: AP코드-72000
B23: 상품/외환 | D23: 퇴직연금 | E23: AP코드-73000
B24: 상품/외환 | D24: 신탁/ISA | E24: AP코드-74000
B25: 상품/외환 | D25: 보험/공제 | E25: AP코드-75000
B26: 상품/외환 | D26: 펀드 | E26: AP코드-76000
B27: 상품/외환 | D27: 골드/주화 | E27: AP코드-77000
B28: 상품/외환 | D28: 청약/채권 | E28: AP코드-78000
B29: 상품/외환 | D29: 카드 | E29: AP코드-79000
B30: 공통 | C30: 고객센터 | E30: AP코드-80000
B31: 공통 | C31: 영업점 | E31: AP코드-81000
B32: 공통 | C32: 이벤트/마케팅 | E32: AP코드-82000
B33: 공통 | C33: 설정 | E33: AP코드-83000
B34: 공통 | C34: 알림함 | E34: AP코드-84000
B35: 모바일 | C35: 모바일웹 | E35: AP코드-85000
B36: 모바일 | C36: 다국어 | E36: AP코드-86000
B37: 모바일 | C37: 태블릿 | E37: AP코드-87000
B38: 모바일 | C38: 위젯 | E38: AP코드-88000

Sheet 감리제출용
A1: Biz요건ID | B1: Biz요건명 | C1: 요구사항구분 | D1: 생성단계 | E1: 상태구분 | F1: 출처 | G1: 요구사항ID | H1: 요구사항명 | I1: 기능/비기능요구사항 | J1: 사용자권한요구사항 | K1: 의뢰부서 | L1: 요구사항처리담당팀 | M1: 검토 상태 | N1: 검토의견 | O1: 변경요구사항ID | P1: 변경일 | Q1: 근기문서 | R1: 수행사 담당자 | S1: 업무상세 | T1: Tech그룹협의필요 대상여부(Y/N) | U1: Tech그룹 유관부서명 | V1: Tech그룹 담당자 | W1: 비고 | X1: IT 담당자 | Y1: ACE담당자 | Z1: 요건협의 미진여부(Y/N) | AA1: IT요건 세부협의 대상 | AB1: Native 협의 대상 | AH1: 요구사항추적표담당자 | AI1: 특이사항 | AJ1: 조건부승인 확정예정일자(YYYY-MM-DD)
A2: Biz-0001 | B2: 공통 | C2: 기능 | D2: 요구사항정의 | E2: 신규 | F2: 구축요건정의서 | G2: BSR-00001 | H2: Login is required | I2: Login is required. Users must authenticate before viewing data. | S2: 공통(로그인/인증) | T2: N | U2: N | X2: 김원용 수석/이상호 팀장/이정윤 대리/전동화 대리 | Y2: 박형준 차장 권장우 대리 | AB2: ● | AH2: 신재현이사
S3: 공통(로그인/인증) | T3: N | U3: N | X3: 김원용 수석 | Y3: 박형준 차장 권장우 대리 | AB3: ● | AH3: 신재현이사
S4: 공통(로그인/인증) | T4: N | U4: 정보보안플랫폼부 | V4: 이민욱 차장 | X4: 이상호 팀장/이정윤 대리/전동화 대리 | Y4: 박형준 차장 권장우 대리 | AB4: ● | AH4: 신재현이사
S5: 공통(로그인/인증) | T5: N | U5: N | X5: 이상호 팀장/이정윤 대리/전동화 대리 | Y5: 박형준 차장 권장우 대리 | AH5: 권영순부장
S6: 공통(로그인/인증) | T6: N | U6: N | X6: 이상호 팀장/이정윤 대리/전동화 대리 | Y6: 박형준 차장 권장우 대리 | AH6: 권영순부장
S7: 네이티브 | T7: N | U7: N | X7: 김원용 수석 | Y7: 박형준 차장 권장우 대리 | AB7: ● | AH7: 신재현이사
S8: 공통(로그인/인증) | T8: N | U8: N | X8: 이상호 팀장/이정윤 대리/전동화 대리 | Y8: 박형준 차장 권장우 대리 | AH8: 권영순부장
S9: 보안/인증 | T9: N | X9: 조형준 대리 | Y9: 이재민 대리 권장우 대리 | AH9: 권영순부장 | AJ9: 44320
S10: 계열사/외부연계 | T10: N | U10: N | X10: 권희영 차장 | Y10: 조세형 과장 이재민 대리 | AH10: 권영순부장 | AI10: [0420]
S11: 계열사/외부연계 | T11: N | U11: N | X11: 권희영 차장 | Y11: 조세형 과장 이재민 대리 | AB11: ● | AH11: 권영순부장
S12: UI/UX | T12: N | U12: N | X12: N/A | Y12: 황인태 차장 정광환 대리 | AH12: 정찬민이사
S13: 공통(기타) | T13: N | U13: N | X13: 이상호 팀장/이정윤 대리/전동화 대리 | Y13: 박형준 차장 권장우 대리 | AH13: 권영순부장
S14: 공통(기타) | T14: N | U14: N | X14: 이상호 팀장/이정윤 대리/전동화 대리 | Y14: 박형준 차장 권장우 대리 | AH14: 권영순부장
S15: 조회 | T15: N | U15: 데이터분석플랫폼부 | V15: 김홍윤 수석 | X15: 조형준 대리 | Y15: 박형준 차장 권장우 대리 | AH15: 이정환부장
S16: 공통(기타) | T16: Y | U16: 코어뱅킹1플랫폼부 | V16: 이향림 과장 | X16: N/A | Y16: 박형준 차장 권장우 대리 | AH16: 권영순부장 | AI16: [0420]
S17: 공통(기타) | T17: N | U17: N | X17: 이상호 팀장/이정윤 대리/전동화 대리 | Y17: 박형준 차장 권장우 대리 | AH17: 권영순부장
S18: 공통(기타) | T18: N | U18: N | X18: 이상호 팀장/이정윤 대리/전동화 대리 | Y18: 박형준 차장 권장우 대리 | AH18: 권영순부장
S19: 개인화 | T19: N | U19: N | X19: 권희영 차장 | Y19: 조세형 과장 | AH19: 권영순부장
S20: 공통(기타) | T20: N | U20: 미래컨택센터추진단 | V20: 송윤종 수석 | X20: N/A | Y20: 박형준 차장 권장우 대리 | AH20: 권영순부장
S21: 네이티브 | T21: N | U21: N | X21: 김원용 수석 | Y21: 박형준 차장 권장우 대리 | AB21: ● | AH21: 신재현이사
S22: 공통(기타) | T22: N | U22: 미래컨택센터추진단 | V22: 송윤종 수석 | X22: 권희영 차장 | Y22: 박형준 차장 권장우 대리 | AH22: 권영순부장
S23: 공통(기타) | T23: N | U23: N | X23: 김원용 수석 | Y23: 박형준 차장 권장우 대리 | AB23: ● | AH23: 권영순부장
S24: 공통(기타) | T24: N | U24: 정보보안플랫폼부 | V24: 이민욱 차장 | X24: 이상호 팀장/이정윤 대리/전동화 대리 | Y24: 박형준 차장 권장우 대리 | AH24: 권영순부장
S25: 공통(기타) | T25: N | U25: 정보보안플랫폼부 | V25: 이민욱 차장 | X25: 이상호 팀장/이정윤 대리/전동화 대리 | Y25: 박형준 차장 권장우 대리 | AH25: 권영순부장 | AI25: [0420]
S26: 공통(기타) | T26: N | U26: 미래컨텍센터추진단 | V26: 김창영 수석 | X26: N/A | Y26: 박형준 차장 권장우 대리 | AH26: 권영순부장
S27: UI/UX | T27: N | U27: N | X27: N/A | Y27: 김민지 대리 | AH27: 정찬민이사
S28: 개인화 | T28: N | U28: 정보보안플랫폼부 | V28: 이민욱 차장 | X28: 이상호 팀장/이정윤 대리/전동화 대리 | Y28: 조세형 과장 | AH28: 권영순부장 | AI28: [0420]
S29: 개인화 | T29: N | U29: N | X29: 이상호 팀장/이정윤 대리/전동화 대리 | Y29: 박형준 차장 권장우 대리 | AH29: 권영순부장 | AI29: [0420]
S30: 메인 | T30: N | U30: N | X30: 권희영 차장/김성학 과장 | Y30: 조세형 과장 | AH30: 권영순부장 | AJ30: 44320
S31: 메인 | T31: Y | U31: N | X31: 권희영 차장/김성학 과장 | Y31: 조세형 과장 박형준 차장 권장우 대리 정관환 대리 최은정 과장 | AH31: 권영순부장 | AI31: [0420]
S32: 네이티브 | T32: N | U32: N | X32: 김원용 수석 | Y32: 조세형 과장 이재민 대리 | AA32: Y | AB32: ● | AH32: 신재현이사 | AJ32: 44320
S33: 네이티브 | T33: N | U33: N | X33: 김원용 수석 | Y33: 김민지 대리 | AB33: ● | AH33: 신재현이사
S34: 공통 | T34: N | U34: N | X34: 공통 | Y34: 김민지 대리 최은정 과장 | AB34: ● | AH34: 정찬민이사
S35: 공통 | T35: N | U35: N | X35: 김원용 수석 | Y35: 최은정 과장 | AB35: ● | AH35: 정찬민이사
S36: 공통 | T36: N | U36: N | X36: 공통 | Y36: 공통 | AH36: 정찬민이사
S37: 메인 | T37: N | U37: 코어뱅킹2플랫폼부 | V37: 전운봉 수석 | W37: 여신업무 | X37: 오의택 대리 | Y37: 조세형 과장 정광환 대리 | AH37: 권영순부장 | AI37: [0420]
S38: 공통(기타) | T38: N | U38: N | X38: 김원용수석/이상호 팀장/이정윤 대리/전동화 대리 | Y38: 박형준 차장 권장우 대리 | AB38: ● | AH38: 권영순부장
S39: 개인화 | T39: N | X39: 최진원 팀장 | Y39: 조세형 과장 | AA39: Y | AB39: ● | AH39: 권영순부장 | AI39: [0420]
S40: 응용개발-공통뱅킹 | T40: N | U40: N | X40: 이득희 팀장 | Y40: N/A | AH40: 권영순부장
...
